ERROR:root:Timeout exceeded.
<pexpect.pty_spawn.spawn object at 0x7f691e8e2198>
command: /usr/bin/ftp
args: ['/usr/bin/ftp', '-p', '146.64.182.213']
searcher: None
buffer (last 100 chars): b'root): user1\r\n331 User user1 OK. Password required\r\nPassword:'
before (last 100 chars): b'root): user1\r\n331 User user1 OK. Password required\r\nPassword:'
after: <class 'pexpect.exceptions.TIMEOUT'>
match: None
match_index: None
exitstatus: None
flag_eof: False
pid: 2972
child_fd: 6
closed: False
timeout: 30
delimiter: <class 'pexpect.exceptions.EOF'>
logfile: None
logfile_read: None
logfile_send: None
maxread: 2000
ignorecase: False
searchwindowsize: None
delaybeforesend: 0.05
delayafterclose: 0.1
delayafterterminate: 0.1
Traceback (most recent call last):
  File "/usr/lib/python3/dist-packages/pexpect/expect.py", line 97, in expect_loop
    incoming = spawn.read_nonblocking(spawn.maxread, timeout)
  File "/usr/lib/python3/dist-packages/pexpect/pty_spawn.py", line 452, in read_nonblocking
    raise TIMEOUT('Timeout exceeded.')
pexpect.exceptions.TIMEOUT: Timeout exceeded.

During handling of the above exception, another exception occurred:

Traceback (most recent call last):
  File "attackerScript.py", line 127, in execute_ftp_login_anon_user
    child.expect(">")
  File "/usr/lib/python3/dist-packages/pexpect/spawnbase.py", line 315, in expect
    timeout, searchwindowsize, async)
  File "/usr/lib/python3/dist-packages/pexpect/spawnbase.py", line 339, in expect_list
    return exp.expect_loop(timeout)
  File "/usr/lib/python3/dist-packages/pexpect/expect.py", line 104, in expect_loop
    return self.timeout(e)
  File "/usr/lib/python3/dist-packages/pexpect/expect.py", line 68, in timeout
    raise TIMEOUT(msg)
pexpect.exceptions.TIMEOUT: Timeout exceeded.
<pexpect.pty_spawn.spawn object at 0x7f691e8e2198>
command: /usr/bin/ftp
args: ['/usr/bin/ftp', '-p', '146.64.182.213']
searcher: None
buffer (last 100 chars): b'root): user1\r\n331 User user1 OK. Password required\r\nPassword:'
before (last 100 chars): b'root): user1\r\n331 User user1 OK. Password required\r\nPassword:'
after: <class 'pexpect.exceptions.TIMEOUT'>
match: None
match_index: None
exitstatus: None
flag_eof: False
pid: 2972
child_fd: 6
closed: False
timeout: 30
delimiter: <class 'pexpect.exceptions.EOF'>
logfile: None
logfile_read: None
logfile_send: None
maxread: 2000
ignorecase: False
searchwindowsize: None
delaybeforesend: 0.05
delayafterclose: 0.1
delayafterterminate: 0.1
ERROR:root:'NoneType' object has no attribute 'items'
Traceback (most recent call last):
  File "attackerScript.py", line 45, in generate_random_request
    for key, val in service_array.items():
AttributeError: 'NoneType' object has no attribute 'items'
ERROR:root:'NoneType' object has no attribute 'items'
Traceback (most recent call last):
  File "attackerScript.py", line 45, in generate_random_request
    for key, val in service_array.items():
AttributeError: 'NoneType' object has no attribute 'items'
ERROR:root:'NoneType' object has no attribute 'items'
Traceback (most recent call last):
  File "attackerScript.py", line 45, in generate_random_request
    for key, val in service_array.items():
AttributeError: 'NoneType' object has no attribute 'items'
ERROR:root:0
Traceback (most recent call last):
  File "attackerScript.py", line 46, in generate_random_request
    current_ip = val[0].get("IP")
KeyError: 0
ERROR:root:0
Traceback (most recent call last):
  File "attackerScript.py", line 46, in generate_random_request
    current_ip = val[0].get("IP")
KeyError: 0
ERROR:root:0
Traceback (most recent call last):
  File "attackerScript.py", line 46, in generate_random_request
    current_ip = val[0].get("IP")
KeyError: 0
ERROR:root:0
Traceback (most recent call last):
  File "attackerScript.py", line 46, in generate_random_request
    current_ip = val[0].get("IP")
KeyError: 0
ERROR:root:0
Traceback (most recent call last):
  File "attackerScript.py", line 48, in generate_random_request
    current_ip = val[0].get("IP")
KeyError: 0
ERROR:root:0
Traceback (most recent call last):
  File "attackerScript.py", line 48, in generate_random_request
    current_ip = val[0].get("IP")
KeyError: 0
ERROR:root:0
Traceback (most recent call last):
  File "attackerScript.py", line 48, in generate_random_request
    current_ip = val[0].get("IP")
KeyError: 0
ERROR:root:0
Traceback (most recent call last):
  File "attackerScript.py", line 48, in generate_random_request
    current_ip = val[0].get("IP")
KeyError: 0
ERROR:root:0
Traceback (most recent call last):
  File "attackerScript.py", line 48, in generate_random_request
    current_ip = val[0].get("IP")
KeyError: 0
ERROR:root:0
Traceback (most recent call last):
  File "attackerScript.py", line 48, in generate_random_request
    current_ip = val[0].get("IP")
KeyError: 0
ERROR:root:0
Traceback (most recent call last):
  File "attackerScript.py", line 47, in generate_random_request
    current_ip = val[0].get("IP")
KeyError: 0
ERROR:root:type object 'attackerClass' has no attribute ''
Traceback (most recent call last):
  File "attackerScript.py", line 82, in call_class_method
    the_method = getattr(attackerClass,method)(values)
AttributeError: type object 'attackerClass' has no attribute ''
