ERROR:root:(2003, "Can't connect to MySQL server on '146.64.182.136.10.41' ([Errno -2] Name or service not known)")
Traceback (most recent call last):
  File "/home/alex/.local/lib/python3.5/site-packages/pymysql/connections.py", line 920, in connect
    **kwargs)
  File "/usr/lib/python3.5/socket.py", line 693, in create_connection
    for res in getaddrinfo(host, port, 0, SOCK_STREAM):
  File "/usr/lib/python3.5/socket.py", line 732, in getaddrinfo
    for res in _socket.getaddrinfo(host, port, family, type, proto, flags):
socket.gaierror: [Errno -2] Name or service not known

During handling of the above exception, another exception occurred:

Traceback (most recent call last):
  File "DataAccess.py", line 54, in get_mysql_connection
    connection = pymysql.connect(host=hostname, user=username, password=password, database=database, cursorclass=pymysql.cursors.DictCursor)
  File "/home/alex/.local/lib/python3.5/site-packages/pymysql/__init__.py", line 90, in Connect
    return Connection(*args, **kwargs)
  File "/home/alex/.local/lib/python3.5/site-packages/pymysql/connections.py", line 699, in __init__
    self.connect()
  File "/home/alex/.local/lib/python3.5/site-packages/pymysql/connections.py", line 967, in connect
    raise exc
pymysql.err.OperationalError: (2003, "Can't connect to MySQL server on '146.64.182.136.10.41' ([Errno -2] Name or service not known)")
