ERROR:root:list index out of range
Traceback (most recent call last):
  File "attackerScript.py", line 537, in get_data
    items=[{'Service':service['service_name'],'IP':servers[i-1]['ip_addr'],'User':servers[i-1]['username'],'Password':servers[i-1]['password'],'Method':actions['method']}]
IndexError: list index out of range
ERROR:root:Timeout exceeded.
<pexpect.pty_spawn.spawn object at 0x7f88f0930dd8>
command: /usr/bin/ftp
args: ['/usr/bin/ftp', '-p', '10.0.5.31']
searcher: None
buffer (last 100 chars): b'alex): ftpserver1\r\n331 User ftpserver1 OK. Password required\r\nPassword:'
before (last 100 chars): b'alex): ftpserver1\r\n331 User ftpserver1 OK. Password required\r\nPassword:'
after: <class 'pexpect.exceptions.TIMEOUT'>
match: None
match_index: None
exitstatus: None
flag_eof: False
pid: 4786
child_fd: 6
closed: False
timeout: 30
delimiter: <class 'pexpect.exceptions.EOF'>
logfile: None
logfile_read: None
logfile_send: None
maxread: 2000
ignorecase: False
searchwindowsize: None
delaybeforesend: 0.05
delayafterclose: 0.1
delayafterterminate: 0.1
Traceback (most recent call last):
  File "/usr/lib/python3/dist-packages/pexpect/expect.py", line 97, in expect_loop
    incoming = spawn.read_nonblocking(spawn.maxread, timeout)
  File "/usr/lib/python3/dist-packages/pexpect/pty_spawn.py", line 452, in read_nonblocking
    raise TIMEOUT('Timeout exceeded.')
pexpect.exceptions.TIMEOUT: Timeout exceeded.

During handling of the above exception, another exception occurred:

Traceback (most recent call last):
  File "attackerScript.py", line 188, in execute_ftp_get_anon_file
    child.expect(">")
  File "/usr/lib/python3/dist-packages/pexpect/spawnbase.py", line 315, in expect
    timeout, searchwindowsize, async)
  File "/usr/lib/python3/dist-packages/pexpect/spawnbase.py", line 339, in expect_list
    return exp.expect_loop(timeout)
  File "/usr/lib/python3/dist-packages/pexpect/expect.py", line 104, in expect_loop
    return self.timeout(e)
  File "/usr/lib/python3/dist-packages/pexpect/expect.py", line 68, in timeout
    raise TIMEOUT(msg)
pexpect.exceptions.TIMEOUT: Timeout exceeded.
<pexpect.pty_spawn.spawn object at 0x7f88f0930dd8>
command: /usr/bin/ftp
args: ['/usr/bin/ftp', '-p', '10.0.5.31']
searcher: None
buffer (last 100 chars): b'alex): ftpserver1\r\n331 User ftpserver1 OK. Password required\r\nPassword:'
before (last 100 chars): b'alex): ftpserver1\r\n331 User ftpserver1 OK. Password required\r\nPassword:'
after: <class 'pexpect.exceptions.TIMEOUT'>
match: None
match_index: None
exitstatus: None
flag_eof: False
pid: 4786
child_fd: 6
closed: False
timeout: 30
delimiter: <class 'pexpect.exceptions.EOF'>
logfile: None
logfile_read: None
logfile_send: None
maxread: 2000
ignorecase: False
searchwindowsize: None
delaybeforesend: 0.05
delayafterclose: 0.1
delayafterterminate: 0.1
ERROR:root:list index out of range
Traceback (most recent call last):
  File "attackerScript.py", line 537, in get_data
    items=[{'Service':service['service_name'],'IP':servers[i-1]['ip_addr'],'User':servers[i-1]['username'],'Password':servers[i-1]['password'],'Method':actions['method']}]
IndexError: list index out of range
ERROR:root:list index out of range
Traceback (most recent call last):
  File "attackerScript.py", line 537, in get_data
    items=[{'Service':service['service_name'],'IP':servers[i-1]['ip_addr'],'User':servers[i-1]['username'],'Password':servers[i-1]['password'],'Method':actions['method']}]
IndexError: list index out of range
ERROR:root:list index out of range
Traceback (most recent call last):
  File "attackerScript.py", line 537, in get_data
    items=[{'Service':service['service_name'],'IP':servers[i-1]['ip_addr'],'User':servers[i-1]['username'],'Password':servers[i-1]['password'],'Method':actions['method']}]
IndexError: list index out of range
ERROR:root:list index out of range
Traceback (most recent call last):
  File "attackerScript.py", line 537, in get_data
    items=[{'Service':service['service_name'],'IP':servers[i]['ip_addr'],'User':servers[i]['username'],'Password':servers[i]['password'],'Method':actions['method']}]
IndexError: list index out of range
ERROR:root:list index out of range
Traceback (most recent call last):
  File "attackerScript.py", line 538, in get_data
    items=[{'Service':service['service_name'],'IP':servers[i]['ip_addr'],'User':servers[i]['username'],'Password':servers[i]['password'],'Method':actions['method']}]
IndexError: list index out of range
ERROR:root:list index out of range
Traceback (most recent call last):
  File "attackerScript.py", line 538, in get_data
    items=[{'Service':service['service_name'],'IP':servers[i]['ip_addr'],'User':servers[i]['username'],'Password':servers[i]['password'],'Method':actions['method']}]
IndexError: list index out of range
ERROR:root:list index out of range
Traceback (most recent call last):
  File "attackerScript.py", line 537, in get_data
    items=[{'Service':service['service_name'],'IP':servers[i]['ip_addr'],'User':servers[i]['username'],'Password':servers[i]['password'],'Method':actions['method']}]
IndexError: list index out of range
ERROR:root:list index out of range
Traceback (most recent call last):
  File "attackerScript.py", line 537, in get_data
    items=[{'Service':service['service_name'],'IP':servers[i]['ip_addr'],'User':servers[i]['username'],'Password':servers[i]['password'],'Method':actions['method']}]
IndexError: list index out of range
ERROR:root:list index out of range
Traceback (most recent call last):
  File "attackerScript.py", line 537, in get_data
    items=[{'Service':service['service_name'],'IP':servers[i]['ip_addr'],'User':servers[i]['username'],'Password':servers[i]['password'],'Method':actions['method']}]
IndexError: list index out of range
ERROR:root:list index out of range
Traceback (most recent call last):
  File "attackerScript.py", line 539, in get_data
    items=[{'Service':service['service_name'],'IP':servers[i]['ip_addr'],'User':servers[i]['username'],'Password':servers[i]['password'],'Method':actions['method']}]
IndexError: list index out of range
ERROR:root:list index out of range
Traceback (most recent call last):
  File "attackerScript.py", line 540, in get_data
    items=[{'Service':service['service_name'],'IP':servers[i]['ip_addr'],'User':servers[i]['username'],'Password':servers[i]['password'],'Method':actions['method']}]
IndexError: list index out of range
ERROR:root:list index out of range
Traceback (most recent call last):
  File "attackerScript.py", line 540, in get_data
    items=[{'Service':service['service_name'],'IP':servers[i]['ip_addr'],'User':servers[i]['username'],'Password':servers[i]['password'],'Method':actions['method']}]
IndexError: list index out of range
ERROR:root:'dict' object has no attribute 'key'
Traceback (most recent call last):
  File "attackerScript.py", line 47, in generate_random_request
    for values in service_array.key():
AttributeError: 'dict' object has no attribute 'key'
ERROR:root:list index out of range
Traceback (most recent call last):
  File "attackerScript.py", line 540, in get_data
    items=[{'Service':service['service_name'],'IP':servers[i]['ip_addr'],'User':servers[i]['username'],'Password':servers[i]['password'],'Method':actions['method']}]
IndexError: list index out of range
ERROR:root:'int' object is not iterable
Traceback (most recent call last):
  File "attackerScript.py", line 47, in generate_random_request
    for values,x in service_array:
TypeError: 'int' object is not iterable
ERROR:root:list index out of range
Traceback (most recent call last):
  File "attackerScript.py", line 540, in get_data
    items=[{'Service':service['service_name'],'IP':servers[i]['ip_addr'],'User':servers[i]['username'],'Password':servers[i]['password'],'Method':actions['method']}]
IndexError: list index out of range
ERROR:root:list index out of range
Traceback (most recent call last):
  File "attackerScript.py", line 540, in get_data
    items=[{'Service':service['service_name'],'IP':servers[i]['ip_addr'],'User':servers[i]['username'],'Password':servers[i]['password'],'Method':actions['method']}]
IndexError: list index out of range
ERROR:root:'int' object is not subscriptable
Traceback (most recent call last):
  File "attackerScript.py", line 48, in generate_random_request
    print(values,x[1])
TypeError: 'int' object is not subscriptable
ERROR:root:list index out of range
Traceback (most recent call last):
  File "attackerScript.py", line 540, in get_data
    items=[{'Service':service['service_name'],'IP':servers[i]['ip_addr'],'User':servers[i]['username'],'Password':servers[i]['password'],'Method':actions['method']}]
IndexError: list index out of range
ERROR:root:'int' object is not subscriptable
Traceback (most recent call last):
  File "attackerScript.py", line 48, in generate_random_request
    print(values,x["IP"])
TypeError: 'int' object is not subscriptable
ERROR:root:list index out of range
Traceback (most recent call last):
  File "attackerScript.py", line 540, in get_data
    items=[{'Service':service['service_name'],'IP':servers[i]['ip_addr'],'User':servers[i]['username'],'Password':servers[i]['password'],'Method':actions['method']}]
IndexError: list index out of range
ERROR:root:'int' object is not subscriptable
Traceback (most recent call last):
  File "attackerScript.py", line 48, in generate_random_request
    print(values,x[0]["IP"])
TypeError: 'int' object is not subscriptable
ERROR:root:list index out of range
Traceback (most recent call last):
  File "attackerScript.py", line 540, in get_data
    items=[{'Service':service['service_name'],'IP':servers[i]['ip_addr'],'User':servers[i]['username'],'Password':servers[i]['password'],'Method':actions['method']}]
IndexError: list index out of range
ERROR:root:list index out of range
Traceback (most recent call last):
  File "attackerScript.py", line 540, in get_data
    items=[{'Service':service['service_name'],'IP':servers[i]['ip_addr'],'User':servers[i]['username'],'Password':servers[i]['password'],'Method':actions['method']}]
IndexError: list index out of range
ERROR:root:'int' object is not subscriptable
Traceback (most recent call last):
  File "attackerScript.py", line 48, in generate_random_request
    print(values[0][0])
TypeError: 'int' object is not subscriptable
ERROR:root:list index out of range
Traceback (most recent call last):
  File "attackerScript.py", line 540, in get_data
    items=[{'Service':service['service_name'],'IP':servers[i]['ip_addr'],'User':servers[i]['username'],'Password':servers[i]['password'],'Method':actions['method']}]
IndexError: list index out of range
ERROR:root:'int' object is not subscriptable
Traceback (most recent call last):
  File "attackerScript.py", line 48, in generate_random_request
    print(values[0]["IP"])
TypeError: 'int' object is not subscriptable
ERROR:root:list index out of range
Traceback (most recent call last):
  File "attackerScript.py", line 538, in get_data
    items=[{'Service':service['service_name'],'IP':servers[i]['ip_addr'],'User':servers[i]['username'],'Password':servers[i]['password'],'Method':actions['method']}]
IndexError: list index out of range
ERROR:root:list index out of range
Traceback (most recent call last):
  File "attackerScript.py", line 538, in get_data
    items=[{'Service':service['service_name'],'IP':servers[i]['ip_addr'],'User':servers[i]['username'],'Password':servers[i]['password'],'Method':actions['method']}]
IndexError: list index out of range
ERROR:root:list index out of range
Traceback (most recent call last):
  File "attackerScript.py", line 539, in get_data
    items=[{'Service':service['service_name'],'IP':servers[i]['ip_addr'],'User':servers[i]['username'],'Password':servers[i]['password'],'Method':actions['method']}]
IndexError: list index out of range
ERROR:root:list index out of range
Traceback (most recent call last):
  File "attackerScript.py", line 539, in get_data
    items=[{'Service':service['service_name'],'IP':servers[i]['ip_addr'],'User':servers[i]['username'],'Password':servers[i]['password'],'Method':actions['method']}]
IndexError: list index out of range
ERROR:root:list index out of range
Traceback (most recent call last):
  File "attackerScript.py", line 539, in get_data
    items=[{'Service':service['service_name'],'IP':servers[i]['ip_addr'],'User':servers[i]['username'],'Password':servers[i]['password'],'Method':actions['method']}]
IndexError: list index out of range
ERROR:root:list index out of range
Traceback (most recent call last):
  File "attackerScript.py", line 539, in get_data
    items=[{'Service':service['service_name'],'IP':servers[i]['ip_addr'],'User':servers[i]['username'],'Password':servers[i]['password'],'Method':actions['method']}]
IndexError: list index out of range
ERROR:root:list index out of range
Traceback (most recent call last):
  File "attackerScript.py", line 539, in get_data
    items=[{'Service':service['service_name'],'IP':servers[i]['ip_addr'],'User':servers[i]['username'],'Password':servers[i]['password'],'Method':actions['method']}]
IndexError: list index out of range
ERROR:root:list index out of range
Traceback (most recent call last):
  File "attackerScript.py", line 541, in get_data
    items=[{'Service':service['service_name'],'IP':servers[i]['ip_addr'],'User':servers[i]['username'],'Password':servers[i]['password'],'Method':actions['method']}]
IndexError: list index out of range
ERROR:root:list index out of range
Traceback (most recent call last):
  File "attackerScript.py", line 541, in get_data
    items=[{'Service':service['service_name'],'IP':servers[i]['ip_addr'],'User':servers[i]['username'],'Password':servers[i]['password'],'Method':actions['method']}]
IndexError: list index out of range
ERROR:root:list index out of range
Traceback (most recent call last):
  File "attackerScript.py", line 541, in get_data
    items=[{'Service':service['service_name'],'IP':servers[i]['ip_addr'],'User':servers[i]['username'],'Password':servers[i]['password'],'Method':actions['method']}]
IndexError: list index out of range
ERROR:root:list index out of range
Traceback (most recent call last):
  File "attackerScript.py", line 538, in get_data
    items=[{'Service':service['service_name'],'IP':servers[i]['ip_addr'],'User':servers[i]['username'],'Password':servers[i]['password'],'Method':actions['method']}]
IndexError: list index out of range
ERROR:root:list index out of range
Traceback (most recent call last):
  File "attackerScript.py", line 538, in get_data
    items=[{'Service':service['service_name'],'IP':servers[i]['ip_addr'],'User':servers[i]['username'],'Password':servers[i]['password'],'Method':actions['method']}]
IndexError: list index out of range
ERROR:root:list index out of range
Traceback (most recent call last):
  File "attackerScript.py", line 538, in get_data
    items=[{'Service':service['service_name'],'IP':servers[i]['ip_addr'],'User':servers[i]['username'],'Password':servers[i]['password'],'Method':actions['method']}]
IndexError: list index out of range
ERROR:root:list index out of range
Traceback (most recent call last):
  File "attackerScript.py", line 538, in get_data
    items=[{'Service':service['service_name'],'IP':servers[i]['ip_addr'],'User':servers[i]['username'],'Password':servers[i]['password'],'Method':actions['method']}]
IndexError: list index out of range
ERROR:root:object of type 'function' has no len()
Traceback (most recent call last):
  File "attackerScript.py", line 47, in generate_random_request
    print(len(service_array))
TypeError: object of type 'function' has no len()
ERROR:root:'function' object has no attribute 'items'
Traceback (most recent call last):
  File "attackerScript.py", line 46, in generate_random_request
    for key, val in service_array.items():
AttributeError: 'function' object has no attribute 'items'
ERROR:root:'function' object has no attribute 'items'
Traceback (most recent call last):
  File "attackerScript.py", line 47, in generate_random_request
    for key, val in service_array.items():
AttributeError: 'function' object has no attribute 'items'
ERROR:root:'function' object has no attribute 'items'
Traceback (most recent call last):
  File "attackerScript.py", line 47, in generate_random_request
    for key, val in service_array.items():
AttributeError: 'function' object has no attribute 'items'
ERROR:root:'function' object has no attribute 'items'
Traceback (most recent call last):
  File "attackerScript.py", line 47, in generate_random_request
    for key, val in service_array.items():
AttributeError: 'function' object has no attribute 'items'
ERROR:root:list indices must be integers or slices, not str
Traceback (most recent call last):
  File "attackerScript.py", line 537, in get_data
    items=[{'Service':service['service_name'],'IP':servers[i-1]['ip_addr'],'User':servers[i-1]['username'],'Password':servers[i-1]['password'],'Method':actions['method']}]
TypeError: list indices must be integers or slices, not str
ERROR:root:list indices must be integers or slices, not str
Traceback (most recent call last):
  File "attackerScript.py", line 537, in get_data
    items=[{'Service':service['service_name'],'IP':servers[i-1]['ip_addr'],'User':servers[i-1]['username'],'Password':servers[i-1]['password'],'Method':actions['method']}]
TypeError: list indices must be integers or slices, not str
ERROR:root:list indices must be integers or slices, not str
Traceback (most recent call last):
  File "attackerScript.py", line 537, in get_data
    items=[{'Service':service['service_name'],'IP':servers[i-1]['ip_addr'],'User':servers[i-1]['username'],'Password':servers[i-1]['password'],'Method':actions['method']}]
TypeError: list indices must be integers or slices, not str
ERROR:root:list indices must be integers or slices, not str
Traceback (most recent call last):
  File "attackerScript.py", line 537, in get_data
    items=[{'Service':service['service_name'],'IP':servers[i-1]['ip_addr'],'User':servers[i-1]['username'],'Password':servers[i-1]['password'],'Method':actions['method']}]
TypeError: list indices must be integers or slices, not str
ERROR:root:'NoneType' object has no attribute 'items'
Traceback (most recent call last):
  File "attackerScript.py", line 47, in generate_random_request
    for key, val in service_array.items():
AttributeError: 'NoneType' object has no attribute 'items'
ERROR:root:list indices must be integers or slices, not str
Traceback (most recent call last):
  File "attackerScript.py", line 540, in get_data
    items=[{'Service':service['service_name'],'IP':servers[i-1]['ip_addr'],'User':servers[i-1]['username'],'Password':servers[i-1]['password'],'Method':actions['method']}]
TypeError: list indices must be integers or slices, not str
ERROR:root:'NoneType' object has no attribute 'items'
Traceback (most recent call last):
  File "attackerScript.py", line 47, in generate_random_request
    for key, val in service_array.items():
AttributeError: 'NoneType' object has no attribute 'items'
ERROR:root:list indices must be integers or slices, not str
Traceback (most recent call last):
  File "attackerScript.py", line 540, in get_data
    items=[{'Service':service['service_name'],'IP':servers[i-1]['ip_addr'],'User':servers[i-1]['username'],'Password':servers[i-1]['password'],'Method':actions['method']}]
TypeError: list indices must be integers or slices, not str
ERROR:root:list indices must be integers or slices, not str
Traceback (most recent call last):
  File "attackerScript.py", line 541, in get_data
    items=[{'Service':service['service_name'],'IP':servers[i-1]['ip_addr'],'User':servers[i-1]['username'],'Password':servers[i-1]['password'],'Method':actions['method']}]
TypeError: list indices must be integers or slices, not str
ERROR:root:list index out of range
Traceback (most recent call last):
  File "attackerScript.py", line 541, in get_data
    items=[{'Service':service['service_name'],'IP':servers[i-1]['ip_addr'],'User':servers[i-1]['username'],'Password':servers[i-1]['password'],'Method':actions[i-1]['method']}]
IndexError: list index out of range
ERROR:root:list index out of range
Traceback (most recent call last):
  File "attackerScript.py", line 537, in get_data
    items=[{'Service':service['service_name'],'IP':servers[i-1]['ip_addr'],'User':servers[i-1]['username'],'Password':servers[i-1]['password'],'Method':actions[i-1]['method']}]
IndexError: list index out of range
ERROR:root:list index out of range
Traceback (most recent call last):
  File "attackerScript.py", line 539, in get_data
    items=[{'Service':service['service_name'],'IP':servers[i-1]['ip_addr'],'User':servers[i-1]['username'],'Password':servers[i-1]['password'],'Method':actions[i-1]['method']}]
IndexError: list index out of range
ERROR:root:list index out of range
Traceback (most recent call last):
  File "attackerScript.py", line 535, in get_data
    items=[{'Service':service['service_name'],'IP':servers[i-1]['ip_addr'],'User':servers[i-1]['username'],'Password':servers[i-1]['password'],'Method':actions[i-1]['method']}]
IndexError: list index out of range
ERROR:root:list index out of range
Traceback (most recent call last):
  File "attackerScript.py", line 535, in get_data
    items=[{'Service':service['service_name'],'IP':servers[i]['ip_addr'],'User':servers[i]['username'],'Password':servers[i]['password'],'Method':actions[i]['method']}]
IndexError: list index out of range
ERROR:root:list index out of range
Traceback (most recent call last):
  File "attackerScript.py", line 535, in get_data
    items=[{'Service':service['service_name'],'IP':servers[i]['ip_addr'],'User':servers[i]['username'],'Password':servers[i]['password'],'Method':actions[i]['method']}]
IndexError: list index out of range
ERROR:root:list index out of range
Traceback (most recent call last):
  File "attackerScript.py", line 535, in get_data
    items=[{'Service':service['service_name'],'IP':servers[i-1]['ip_addr'],'User':servers[i-1]['username'],'Password':servers[i-1]['password'],'Method':actions[i-1]['method']}]
IndexError: list index out of range
ERROR:root:list index out of range
Traceback (most recent call last):
  File "attackerScript.py", line 536, in get_data
    items=[{'Service':service['service_name'],'IP':servers[i-1]['ip_addr'],'User':servers[i-1]['username'],'Password':servers[i-1]['password'],'Method':actions[i-1]['method']}]
IndexError: list index out of range
ERROR:root:list index out of range
Traceback (most recent call last):
  File "attackerScript.py", line 535, in get_data
    items=[{'Service':service['service_name'],'IP':servers[i-1]['ip_addr'],'User':servers[i-1]['username'],'Password':servers[i-1]['password'],'Method':actions[i-1]['method']}]
IndexError: list index out of range
ERROR:root:list index out of range
Traceback (most recent call last):
  File "attackerScript.py", line 535, in get_data
    items=[{'Service':service['service_name'],'IP':servers[i-1]['ip_addr'],'User':servers[i-1]['username'],'Password':servers[i-1]['password'],'Method':actions[i-1]['method']}]
IndexError: list index out of range
ERROR:root:list index out of range
Traceback (most recent call last):
  File "attackerScript.py", line 535, in get_data
    items=[{'Service':service['service_name'],'IP':servers[i-1]['ip_addr'],'User':servers[i-1]['username'],'Password':servers[i-1]['password'],'Method':actions[i-1]['method']}]
IndexError: list index out of range
ERROR:root:list index out of range
Traceback (most recent call last):
  File "attackerScript.py", line 535, in get_data
    items=[{'Service':service['service_name'],'IP':servers[i-1]['ip_addr'],'User':servers[i-1]['username'],'Password':servers[i-1]['password'],'Method':actions[i-1]['method']}]
IndexError: list index out of range
ERROR:root:list index out of range
Traceback (most recent call last):
  File "attackerScript.py", line 535, in get_data
    items=[{'Service':service['service_name'],'IP':servers[i-1]['ip_addr'],'User':servers[i-1]['username'],'Password':servers[i-1]['password'],'Method':actions[i-1]['method']}]
IndexError: list index out of range
ERROR:root:list index out of range
Traceback (most recent call last):
  File "attackerScript.py", line 535, in get_data
    items=[{'Service':service['service_name'],'IP':servers[i-1]['ip_addr'],'User':servers[i-1]['username'],'Password':servers[i-1]['password'],'Method':actions[i-1]['method']}]
IndexError: list index out of range
ERROR:root:list index out of range
Traceback (most recent call last):
  File "attackerScript.py", line 535, in get_data
    items=[{'Service':service['service_name'],'IP':servers[i-1]['ip_addr'],'User':servers[i-1]['username'],'Password':servers[i-1]['password'],'Method':actions[i-1]['method']}]
IndexError: list index out of range
ERROR:root:object of type 'int' has no len()
Traceback (most recent call last):
  File "attackerScript.py", line 523, in get_data
    count=len(server_count)
TypeError: object of type 'int' has no len()
ERROR:root:type object 'attacker' has no attribute 'servers'
Traceback (most recent call last):
  File "attackerScript.py", line 523, in get_data
    count=len(attacker.servers)
AttributeError: type object 'attacker' has no attribute 'servers'
ERROR:root:type object 'attacker' has no attribute 'servers'
Traceback (most recent call last):
  File "attackerScript.py", line 524, in get_data
    count=len(attacker.servers)
AttributeError: type object 'attacker' has no attribute 'servers'
ERROR:root:list index out of range
Traceback (most recent call last):
  File "attackerScript.py", line 535, in get_data
    items=[{'Service':service['service_name'],'IP':servers[i-1]['ip_addr'],'User':servers[i-1]['username'],'Password':servers[i-1]['password'],'Method':actions[i-1]['method']}]
IndexError: list index out of range
ERROR:root:list index out of range
Traceback (most recent call last):
  File "attackerScript.py", line 535, in get_data
    items=[{'Service':service['service_name'],'IP':servers[i-1]['ip_addr'],'User':servers[i-1]['username'],'Password':servers[i-1]['password'],'Method':actions[i-1]['method']}]
IndexError: list index out of range
ERROR:root:list index out of range
Traceback (most recent call last):
  File "attackerScript.py", line 535, in get_data
    items=[{'Service':service['service_name'],'IP':servers[i-1]['ip_addr'],'User':servers[i-1]['username'],'Password':servers[i-1]['password'],'Method':actions[i-1]['method']}]
IndexError: list index out of range
ERROR:root:list index out of range
Traceback (most recent call last):
  File "attackerScript.py", line 535, in get_data
    items=[{'Service':service['service_name'],'IP':servers[i-1]['ip_addr'],'User':servers[i-1]['username'],'Password':servers[i-1]['password'],'Method':actions[i-1]['method']}]
IndexError: list index out of range
ERROR:root:range() arg 3 must not be zero
Traceback (most recent call last):
  File "attackerScript.py", line 524, in get_data
    for i in list(range(0,server_count,0)):
ValueError: range() arg 3 must not be zero
ERROR:root:list index out of range
Traceback (most recent call last):
  File "attackerScript.py", line 535, in get_data
    items=[{'Service':service['service_name'],'IP':servers[i-1]['ip_addr'],'User':servers[i-1]['username'],'Password':servers[i-1]['password'],'Method':actions[i-1]['method']}]
IndexError: list index out of range
ERROR:root:list index out of range
Traceback (most recent call last):
  File "attackerScript.py", line 535, in get_data
    items=[{'Service':service['service_name'],'IP':servers[i-1]['ip_addr'],'User':servers[i-1]['username'],'Password':servers[i-1]['password'],'Method':actions[i-1]['method']}]
IndexError: list index out of range
ERROR:root:list index out of range
Traceback (most recent call last):
  File "attackerScript.py", line 535, in get_data
    items=[{'Service':service['service_name'],'IP':servers[i-1]['ip_addr'],'User':servers[i-1]['username'],'Password':servers[i-1]['password'],'Method':actions[i-1]['method']}]
IndexError: list index out of range
ERROR:root:(2014, 'Command Out of Sync')
Traceback (most recent call last):
  File "/home/alex/Documents/GitRepo/IR/DataAccess.py", line 81, in get_servers
    cursor.execute(sql)
  File "/home/alex/.local/lib/python3.5/site-packages/pymysql/cursors.py", line 165, in execute
    result = self._query(query)
  File "/home/alex/.local/lib/python3.5/site-packages/pymysql/cursors.py", line 321, in _query
    conn.query(q)
  File "/home/alex/.local/lib/python3.5/site-packages/pymysql/connections.py", line 860, in query
    self._affected_rows = self._read_query_result(unbuffered=unbuffered)
  File "/home/alex/.local/lib/python3.5/site-packages/pymysql/connections.py", line 1061, in _read_query_result
    result.read()
  File "/home/alex/.local/lib/python3.5/site-packages/pymysql/connections.py", line 1349, in read
    first_packet = self.connection._read_packet()
  File "/home/alex/.local/lib/python3.5/site-packages/pymysql/connections.py", line 991, in _read_packet
    packet_header = self._read_bytes(4)
  File "/home/alex/.local/lib/python3.5/site-packages/pymysql/connections.py", line 1025, in _read_bytes
    data = self._rfile.read(num_bytes)
  File "/usr/lib/python3.5/socket.py", line 575, in readinto
    return self._sock.recv_into(b)
KeyboardInterrupt

During handling of the above exception, another exception occurred:

Traceback (most recent call last):
  File "/home/alex/Documents/GitRepo/IR/DataAccess.py", line 82, in get_servers
    result = cursor.fetchall()
  File "/home/alex/.local/lib/python3.5/site-packages/pymysql/connections.py", line 846, in __exit__
    self.rollback()
  File "/home/alex/.local/lib/python3.5/site-packages/pymysql/connections.py", line 786, in rollback
    self._read_ok_packet()
  File "/home/alex/.local/lib/python3.5/site-packages/pymysql/connections.py", line 762, in _read_ok_packet
    raise err.OperationalError(2014, "Command Out of Sync")
pymysql.err.OperationalError: (2014, 'Command Out of Sync')
ERROR:root:local variable 'result' referenced before assignment
Traceback (most recent call last):
  File "/home/alex/Documents/GitRepo/IR/DataAccess.py", line 179, in get_service
    self.servers=self.data.get_servers(service_id['service_id'])
  File "/home/alex/Documents/GitRepo/IR/DataAccess.py", line 87, in get_servers
    return result
UnboundLocalError: local variable 'result' referenced before assignment
ERROR:root:(0, '')
Traceback (most recent call last):
  File "/home/alex/Documents/GitRepo/IR/DataAccess.py", line 128, in get_action
    cursor.execute(sql)
  File "/home/alex/.local/lib/python3.5/site-packages/pymysql/cursors.py", line 165, in execute
    result = self._query(query)
  File "/home/alex/.local/lib/python3.5/site-packages/pymysql/cursors.py", line 321, in _query
    conn.query(q)
  File "/home/alex/.local/lib/python3.5/site-packages/pymysql/connections.py", line 860, in query
    self._affected_rows = self._read_query_result(unbuffered=unbuffered)
  File "/home/alex/.local/lib/python3.5/site-packages/pymysql/connections.py", line 1061, in _read_query_result
    result.read()
  File "/home/alex/.local/lib/python3.5/site-packages/pymysql/connections.py", line 1349, in read
    first_packet = self.connection._read_packet()
  File "/home/alex/.local/lib/python3.5/site-packages/pymysql/connections.py", line 1005, in _read_packet
    % (packet_number, self._next_seq_id))
pymysql.err.InternalError: Packet sequence number wrong - got 2 expected 1

During handling of the above exception, another exception occurred:

Traceback (most recent call last):
  File "/home/alex/Documents/GitRepo/IR/DataAccess.py", line 129, in get_action
    result = cursor.fetchall()
  File "/home/alex/.local/lib/python3.5/site-packages/pymysql/connections.py", line 846, in __exit__
    self.rollback()
  File "/home/alex/.local/lib/python3.5/site-packages/pymysql/connections.py", line 785, in rollback
    self._execute_command(COMMAND.COM_QUERY, "ROLLBACK")
  File "/home/alex/.local/lib/python3.5/site-packages/pymysql/connections.py", line 1075, in _execute_command
    raise err.InterfaceError("(0, '')")
pymysql.err.InterfaceError: (0, '')
ERROR:root:local variable 'result' referenced before assignment
Traceback (most recent call last):
  File "/home/alex/Documents/GitRepo/IR/DataAccess.py", line 203, in get_action
    action_list=self.data.get_action(service_id)
  File "/home/alex/Documents/GitRepo/IR/DataAccess.py", line 135, in get_action
    return result
UnboundLocalError: local variable 'result' referenced before assignment
ERROR:root:local variable 'action' referenced before assignment
Traceback (most recent call last):
  File "attackerScript.py", line 529, in get_data
    data.fetch_action()
  File "/home/alex/Documents/GitRepo/IR/DataAccess.py", line 306, in fetch_action
    self.actions=self.get_action()
  File "/home/alex/Documents/GitRepo/IR/DataAccess.py", line 219, in get_action
    return action
UnboundLocalError: local variable 'action' referenced before assignment
ERROR:root:list index out of range
Traceback (most recent call last):
  File "attackerScript.py", line 537, in get_data
    items=[{'Service':service['service_name'],'IP':servers[i-1]['ip_addr'],'User':servers[i-1]['username'],'Password':servers[i-1]['password'],'Method':actions[i-1]['method']}]
IndexError: list index out of range
ERROR:root:list index out of range
Traceback (most recent call last):
  File "attackerScript.py", line 535, in get_data
    items=[{'Service':service['service_name'],'IP':servers[i-1]['ip_addr'],'User':servers[i-1]['username'],'Password':servers[i-1]['password'],'Method':actions[i-1]['method']}]
IndexError: list index out of range
ERROR:root:list index out of range
Traceback (most recent call last):
  File "attackerScript.py", line 535, in get_data
    items=[{'Service':service['service_name'],'IP':servers[i-1]['ip_addr'],'User':servers[i-1]['username'],'Password':servers[i-1]['password'],'Method':actions[i-1]['method']}]
IndexError: list index out of range
ERROR:root:list index out of range
Traceback (most recent call last):
  File "attackerScript.py", line 533, in get_data
    print(actions[i-1]['method'])
IndexError: list index out of range
ERROR:root:unsupported operand type(s) for -: 'list' and 'int'
Traceback (most recent call last):
  File "attackerScript.py", line 531, in get_data
    server_count=len(servers-1)
TypeError: unsupported operand type(s) for -: 'list' and 'int'
ERROR:root:unsupported operand type(s) for -: 'list' and 'int'
Traceback (most recent call last):
  File "attackerScript.py", line 531, in get_data
    server_count=len(servers-1)
TypeError: unsupported operand type(s) for -: 'list' and 'int'
ERROR:root:unsupported operand type(s) for -: 'list' and 'int'
Traceback (most recent call last):
  File "attackerScript.py", line 531, in get_data
    server_count=len(servers-1)
TypeError: unsupported operand type(s) for -: 'list' and 'int'
ERROR:root:list index out of range
Traceback (most recent call last):
  File "attackerScript.py", line 533, in get_data
    print(actions[i-1]['method'])
IndexError: list index out of range
ERROR:root:list index out of range
Traceback (most recent call last):
  File "attackerScript.py", line 533, in get_data
    print(actions[i]['method'])
IndexError: list index out of range
ERROR:root:list index out of range
Traceback (most recent call last):
  File "attackerScript.py", line 533, in get_data
    print(actions[i]['method'])
IndexError: list index out of range
ERROR:root:list index out of range
Traceback (most recent call last):
  File "attackerScript.py", line 534, in get_data
    print(actions[i]['method'])
IndexError: list index out of range
ERROR:root:object of type 'int' has no len()
Traceback (most recent call last):
  File "attackerScript.py", line 524, in get_data
    for i in range(len(server_count)):
TypeError: object of type 'int' has no len()
ERROR:root:list index out of range
Traceback (most recent call last):
  File "attackerScript.py", line 534, in get_data
    print(actions[i]['method'])
IndexError: list index out of range
ERROR:root:list index out of range
Traceback (most recent call last):
  File "attackerScript.py", line 535, in get_data
    print(actions[i]['method'])
IndexError: list index out of range
ERROR:root:list index out of range
Traceback (most recent call last):
  File "attackerScript.py", line 534, in get_data
    print(actions[i]['method'])
IndexError: list index out of range
ERROR:root:list index out of range
Traceback (most recent call last):
  File "attackerScript.py", line 534, in get_data
    print(actions[i]['method'])
IndexError: list index out of range
ERROR:root:list index out of range
Traceback (most recent call last):
  File "attackerScript.py", line 534, in get_data
    print(actions[i]['method'])
IndexError: list index out of range
ERROR:root:unorderable types: int() < list()
Traceback (most recent call last):
  File "attackerScript.py", line 533, in get_data
    if i < list(range(server_count)):
TypeError: unorderable types: int() < list()
ERROR:root:unorderable types: int() < range()
Traceback (most recent call last):
  File "attackerScript.py", line 533, in get_data
    if i < range(server_count):
TypeError: unorderable types: int() < range()
ERROR:root:list index out of range
Traceback (most recent call last):
  File "attackerScript.py", line 535, in get_data
    print(actions[i]['method'])
IndexError: list index out of range
ERROR:root:list index out of range
Traceback (most recent call last):
  File "attackerScript.py", line 535, in get_data
    print(actions[i]['method'])
IndexError: list index out of range
ERROR:root:list index out of range
Traceback (most recent call last):
  File "attackerScript.py", line 539, in get_data
    items=[{'Service':service['service_name'],'IP':servers[i]['ip_addr'],'User':servers[i]['username'],'Password':servers[i]['password'],'Method':actions[i]['method']}]
IndexError: list index out of range
ERROR:root:list index out of range
Traceback (most recent call last):
  File "attackerScript.py", line 535, in get_data
    print(actions[i+1]['method'])
IndexError: list index out of range
ERROR:root:list index out of range
Traceback (most recent call last):
  File "attackerScript.py", line 535, in get_data
    print(actions[i+1]['method'])
IndexError: list index out of range
ERROR:root:list() takes at most 1 argument (2 given)
Traceback (most recent call last):
  File "attackerScript.py", line 524, in get_data
    for i in list(0,range(server_counted)):
TypeError: list() takes at most 1 argument (2 given)
ERROR:root:list index out of range
Traceback (most recent call last):
  File "attackerScript.py", line 534, in get_data
    print(actions[i]['method'])
IndexError: list index out of range
ERROR:root:list index out of range
Traceback (most recent call last):
  File "attackerScript.py", line 534, in get_data
    print(actions[i]['method'])
IndexError: list index out of range
ERROR:root:list index out of range
Traceback (most recent call last):
  File "attackerScript.py", line 535, in get_data
    print(actions[i]['method'])
IndexError: list index out of range
ERROR:root:list index out of range
Traceback (most recent call last):
  File "attackerScript.py", line 535, in get_data
    print(actions[i]['method'])
IndexError: list index out of range
ERROR:root:list index out of range
Traceback (most recent call last):
  File "attackerScript.py", line 534, in get_data
    print(actions[i]['method'])
IndexError: list index out of range
ERROR:root:list index out of range
Traceback (most recent call last):
  File "attackerScript.py", line 535, in get_data
    print(servers[i]['ip_addr'])
IndexError: list index out of range
ERROR:root:list index out of range
Traceback (most recent call last):
  File "attackerScript.py", line 534, in get_data
    items=[{'Service':service['service_name'],'IP':servers[i]['ip_addr'],'User':servers[i]['username'],'Password':servers[i]['password'],'Method':actions[i]['method']}]
IndexError: list index out of range
ERROR:root:list index out of range
Traceback (most recent call last):
  File "attackerScript.py", line 534, in get_data
    items=[{'Service':service['service_name'],'IP':servers[i]['ip_addr'],'User':servers[i]['username'],'Password':servers[i]['password'],'Method':actions[i]['method']}]
IndexError: list index out of range
ERROR:root:list index out of range
Traceback (most recent call last):
  File "attackerScript.py", line 534, in get_data
    items=[{'Service':service['service_name'],'IP':servers[i]['ip_addr'],'User':servers[i]['username'],'Password':servers[i]['password'],'Method':actions[i]['method']}]
IndexError: list index out of range
ERROR:root:could not synchronize with original prompt
Traceback (most recent call last):
  File "attackerScript.py", line 473, in execute_ssh_execute_file
    ssh_handle.login(ip, user, password)
  File "/usr/lib/python3/dist-packages/pexpect/pxssh.py", line 333, in login
    raise ExceptionPxssh('could not synchronize with original prompt')
pexpect.pxssh.ExceptionPxssh: could not synchronize with original prompt
ERROR:root:Timeout exceeded.
<pexpect.pty_spawn.spawn object at 0x7fa1a1ac7a20>
command: /usr/bin/ftp
args: ['/usr/bin/ftp', '-p', '10.0.5.31']
searcher: None
buffer (last 100 chars): b'root): ftpserver1\r\n331 User ftpserver1 OK. Password required\r\nPassword:'
before (last 100 chars): b'root): ftpserver1\r\n331 User ftpserver1 OK. Password required\r\nPassword:'
after: <class 'pexpect.exceptions.TIMEOUT'>
match: None
match_index: None
exitstatus: None
flag_eof: False
pid: 6884
child_fd: 6
closed: False
timeout: 30
delimiter: <class 'pexpect.exceptions.EOF'>
logfile: None
logfile_read: None
logfile_send: None
maxread: 2000
ignorecase: False
searchwindowsize: None
delaybeforesend: 0.05
delayafterclose: 0.1
delayafterterminate: 0.1
Traceback (most recent call last):
  File "/usr/lib/python3/dist-packages/pexpect/expect.py", line 97, in expect_loop
    incoming = spawn.read_nonblocking(spawn.maxread, timeout)
  File "/usr/lib/python3/dist-packages/pexpect/pty_spawn.py", line 452, in read_nonblocking
    raise TIMEOUT('Timeout exceeded.')
pexpect.exceptions.TIMEOUT: Timeout exceeded.

During handling of the above exception, another exception occurred:

Traceback (most recent call last):
  File "attackerScript.py", line 160, in execute_ftp_put_anon_file
    child.expect(">")
  File "/usr/lib/python3/dist-packages/pexpect/spawnbase.py", line 315, in expect
    timeout, searchwindowsize, async)
  File "/usr/lib/python3/dist-packages/pexpect/spawnbase.py", line 339, in expect_list
    return exp.expect_loop(timeout)
  File "/usr/lib/python3/dist-packages/pexpect/expect.py", line 104, in expect_loop
    return self.timeout(e)
  File "/usr/lib/python3/dist-packages/pexpect/expect.py", line 68, in timeout
    raise TIMEOUT(msg)
pexpect.exceptions.TIMEOUT: Timeout exceeded.
<pexpect.pty_spawn.spawn object at 0x7fa1a1ac7a20>
command: /usr/bin/ftp
args: ['/usr/bin/ftp', '-p', '10.0.5.31']
searcher: None
buffer (last 100 chars): b'root): ftpserver1\r\n331 User ftpserver1 OK. Password required\r\nPassword:'
before (last 100 chars): b'root): ftpserver1\r\n331 User ftpserver1 OK. Password required\r\nPassword:'
after: <class 'pexpect.exceptions.TIMEOUT'>
match: None
match_index: None
exitstatus: None
flag_eof: False
pid: 6884
child_fd: 6
closed: False
timeout: 30
delimiter: <class 'pexpect.exceptions.EOF'>
logfile: None
logfile_read: None
logfile_send: None
maxread: 2000
ignorecase: False
searchwindowsize: None
delaybeforesend: 0.05
delayafterclose: 0.1
delayafterterminate: 0.1
ERROR:root:Timeout exceeded.
<pexpect.pty_spawn.spawn object at 0x7f63d0eb49b0>
command: /usr/bin/ftp
args: ['/usr/bin/ftp', '-p', '10.0.5.31']
searcher: None
buffer (last 100 chars): b'root): ftpserver1\r\n331 User ftpserver1 OK. Password required\r\nPassword:'
before (last 100 chars): b'root): ftpserver1\r\n331 User ftpserver1 OK. Password required\r\nPassword:'
after: <class 'pexpect.exceptions.TIMEOUT'>
match: None
match_index: None
exitstatus: None
flag_eof: False
pid: 6910
child_fd: 6
closed: False
timeout: 30
delimiter: <class 'pexpect.exceptions.EOF'>
logfile: None
logfile_read: None
logfile_send: None
maxread: 2000
ignorecase: False
searchwindowsize: None
delaybeforesend: 0.05
delayafterclose: 0.1
delayafterterminate: 0.1
Traceback (most recent call last):
  File "/usr/lib/python3/dist-packages/pexpect/expect.py", line 97, in expect_loop
    incoming = spawn.read_nonblocking(spawn.maxread, timeout)
  File "/usr/lib/python3/dist-packages/pexpect/pty_spawn.py", line 452, in read_nonblocking
    raise TIMEOUT('Timeout exceeded.')
pexpect.exceptions.TIMEOUT: Timeout exceeded.

During handling of the above exception, another exception occurred:

Traceback (most recent call last):
  File "attackerScript.py", line 136, in execute_ftp_login_anon_user
    child.expect(">")
  File "/usr/lib/python3/dist-packages/pexpect/spawnbase.py", line 315, in expect
    timeout, searchwindowsize, async)
  File "/usr/lib/python3/dist-packages/pexpect/spawnbase.py", line 339, in expect_list
    return exp.expect_loop(timeout)
  File "/usr/lib/python3/dist-packages/pexpect/expect.py", line 104, in expect_loop
    return self.timeout(e)
  File "/usr/lib/python3/dist-packages/pexpect/expect.py", line 68, in timeout
    raise TIMEOUT(msg)
pexpect.exceptions.TIMEOUT: Timeout exceeded.
<pexpect.pty_spawn.spawn object at 0x7f63d0eb49b0>
command: /usr/bin/ftp
args: ['/usr/bin/ftp', '-p', '10.0.5.31']
searcher: None
buffer (last 100 chars): b'root): ftpserver1\r\n331 User ftpserver1 OK. Password required\r\nPassword:'
before (last 100 chars): b'root): ftpserver1\r\n331 User ftpserver1 OK. Password required\r\nPassword:'
after: <class 'pexpect.exceptions.TIMEOUT'>
match: None
match_index: None
exitstatus: None
flag_eof: False
pid: 6910
child_fd: 6
closed: False
timeout: 30
delimiter: <class 'pexpect.exceptions.EOF'>
logfile: None
logfile_read: None
logfile_send: None
maxread: 2000
ignorecase: False
searchwindowsize: None
delaybeforesend: 0.05
delayafterclose: 0.1
delayafterterminate: 0.1
ERROR:root:(2003, "Can't connect to MySQL server on '146.64.182.136' (timed out)")
Traceback (most recent call last):
  File "/home/alex/.local/lib/python3.5/site-packages/pymysql/connections.py", line 920, in connect
    **kwargs)
  File "/usr/lib/python3.5/socket.py", line 711, in create_connection
    raise err
  File "/usr/lib/python3.5/socket.py", line 702, in create_connection
    sock.connect(sa)
socket.timeout: timed out

During handling of the above exception, another exception occurred:

Traceback (most recent call last):
  File "DataAccess.py", line 45, in get_mysql_connection
    connection = pymysql.connect(host='146.64.182.136', user='myuser', password='1234', database='ir_db',cursorclass=pymysql.cursors.DictCursor)
  File "/home/alex/.local/lib/python3.5/site-packages/pymysql/__init__.py", line 90, in Connect
    return Connection(*args, **kwargs)
  File "/home/alex/.local/lib/python3.5/site-packages/pymysql/connections.py", line 699, in __init__
    self.connect()
  File "/home/alex/.local/lib/python3.5/site-packages/pymysql/connections.py", line 967, in connect
    raise exc
pymysql.err.OperationalError: (2003, "Can't connect to MySQL server on '146.64.182.136' (timed out)")
ERROR:root:list assignment index out of range
Traceback (most recent call last):
  File "DataAccess.py", line 234, in get_action
    server_and_method[i]={'server':self.servers[i],'method':''}
IndexError: list assignment index out of range
ERROR:root:list assignment index out of range
Traceback (most recent call last):
  File "DataAccess.py", line 236, in get_action
    server_and_method[i]={'server':self.servers[i],'method':''}
IndexError: list assignment index out of range
ERROR:root:list assignment index out of range
Traceback (most recent call last):
  File "DataAccess.py", line 236, in get_action
    server_and_method[i]={'server':self.servers[i],'method':''}
IndexError: list assignment index out of range
ERROR:root:list assignment index out of range
Traceback (most recent call last):
  File "DataAccess.py", line 233, in get_action
    server_and_method[i]={'server':self.servers[i],'method':''}
IndexError: list assignment index out of range
ERROR:root:list assignment index out of range
Traceback (most recent call last):
  File "DataAccess.py", line 236, in get_action
    server_and_method[i]={'server':self.servers[i],'method':''}
IndexError: list assignment index out of range
ERROR:root:list index out of range
Traceback (most recent call last):
  File "DataAccess.py", line 223, in get_action
    print(action_list[server_count])
IndexError: list index out of range
ERROR:root:list assignment index out of range
Traceback (most recent call last):
  File "DataAccess.py", line 240, in get_action
    server_and_method[i]={'server':self.servers[i],'method':''}
IndexError: list assignment index out of range
ERROR:root:list assignment index out of range
Traceback (most recent call last):
  File "DataAccess.py", line 240, in get_action
    server_and_method[i]={'server':self.servers[i],'method':''}
IndexError: list assignment index out of range
ERROR:root:(2003, "Can't connect to MySQL server on '192.168.8.126' (timed out)")
Traceback (most recent call last):
  File "/home/alex/.local/lib/python3.5/site-packages/pymysql/connections.py", line 920, in connect
    **kwargs)
  File "/usr/lib/python3.5/socket.py", line 711, in create_connection
    raise err
  File "/usr/lib/python3.5/socket.py", line 702, in create_connection
    sock.connect(sa)
socket.timeout: timed out

During handling of the above exception, another exception occurred:

Traceback (most recent call last):
  File "DataAccess.py", line 45, in get_mysql_connection
    connection = pymysql.connect(host='192.168.8.126', user='myuser', password='1234', database='ir_db',cursorclass=pymysql.cursors.DictCursor)#host=146.64.182.136
  File "/home/alex/.local/lib/python3.5/site-packages/pymysql/__init__.py", line 90, in Connect
    return Connection(*args, **kwargs)
  File "/home/alex/.local/lib/python3.5/site-packages/pymysql/connections.py", line 699, in __init__
    self.connect()
  File "/home/alex/.local/lib/python3.5/site-packages/pymysql/connections.py", line 967, in connect
    raise exc
pymysql.err.OperationalError: (2003, "Can't connect to MySQL server on '192.168.8.126' (timed out)")
ERROR:root:list assignment index out of range
Traceback (most recent call last):
  File "DataAccess.py", line 242, in get_action
    server_and_method[i]={'server':self.servers[i],'method':get_method()}
IndexError: list assignment index out of range
ERROR:root:list assignment index out of range
Traceback (most recent call last):
  File "DataAccess.py", line 242, in get_action
    server_and_method[i]={'server':self.servers[i],'method':get_method()}
IndexError: list assignment index out of range
ERROR:root:list assignment index out of range
Traceback (most recent call last):
  File "DataAccess.py", line 242, in get_action
    server_and_method[i]={'server':self.servers[i],'method':get_method()}
IndexError: list assignment index out of range
ERROR:root:type object 'attacker' has no attribute 'servers_and_methods'
Traceback (most recent call last):
  File "attackerScript.py", line 710, in get_data
    for i in range(0,len(attacker.servers_and_methods)):
AttributeError: type object 'attacker' has no attribute 'servers_and_methods'
ERROR:root:'NoneType' object cannot be interpreted as an integer
Traceback (most recent call last):
  File "attackerScript.py", line 713, in get_data
    for i in range(0,count):
TypeError: 'NoneType' object cannot be interpreted as an integer
ERROR:root:'NoneType' object cannot be interpreted as an integer
Traceback (most recent call last):
  File "attackerScript.py", line 713, in get_data
    for i in range(0,count):
TypeError: 'NoneType' object cannot be interpreted as an integer
ERROR:root:'NoneType' object cannot be interpreted as an integer
Traceback (most recent call last):
  File "attackerScript.py", line 716, in get_data
    for i in range(0,count):
TypeError: 'NoneType' object cannot be interpreted as an integer
ERROR:root:'NoneType' object cannot be interpreted as an integer
Traceback (most recent call last):
  File "attackerScript.py", line 715, in get_data
    for i in range(0,count):
TypeError: 'NoneType' object cannot be interpreted as an integer
ERROR:root:'NoneType' object cannot be interpreted as an integer
Traceback (most recent call last):
  File "attackerScript.py", line 716, in get_data
    for i in range(0,count):
TypeError: 'NoneType' object cannot be interpreted as an integer
ERROR:root:object of type 'NoneType' has no len()
Traceback (most recent call last):
  File "attackerScript.py", line 710, in get_data
    count=len(data.servers_and_methods)
TypeError: object of type 'NoneType' has no len()
ERROR:root:'attacker' object has no attribute 'servers_and_methods'
Traceback (most recent call last):
  File "/home/alex/Documents/GitRepo/IR/DataAccess.py", line 253, in get_action
    self.servers_and_methods.append({'server':self.servers[i],'method':get_method()})
AttributeError: 'attacker' object has no attribute 'servers_and_methods'
ERROR:root:'NoneType' object has no attribute 'items'
Traceback (most recent call last):
  File "attackerScript.py", line 47, in generate_random_request
    for key, val in service_array.items():
AttributeError: 'NoneType' object has no attribute 'items'
ERROR:root:'NoneType' object has no attribute 'items'
Traceback (most recent call last):
  File "attackerScript.py", line 47, in generate_random_request
    for key, val in service_array.items():
AttributeError: 'NoneType' object has no attribute 'items'
ERROR:root:The command was not found or was not executable: hydra.
Traceback (most recent call last):
  File "attackerScript.py", line 104, in hydra_spawn
    child = pexpect.spawn(command)
  File "/usr/lib/python3/dist-packages/pexpect/pty_spawn.py", line 194, in __init__
    self._spawn(command, args, preexec_fn, dimensions)
  File "/usr/lib/python3/dist-packages/pexpect/pty_spawn.py", line 267, in _spawn
    'executable: %s.' % self.command)
pexpect.exceptions.ExceptionPexpect: The command was not found or was not executable: hydra.
ERROR:root:'DataAccess' object has no attribute 'service_count'
Traceback (most recent call last):
  File "/home/alex/Documents/GitRepo/IR/DataAccess.py", line 140, in get_service
    service_count=self.data.service_count
AttributeError: 'DataAccess' object has no attribute 'service_count'
ERROR:root:'NoneType' object is not subscriptable
Traceback (most recent call last):
  File "/home/alex/Documents/GitRepo/IR/DataAccess.py", line 184, in get_action
    service_id=self.service['service_id']
TypeError: 'NoneType' object is not subscriptable
ERROR:root:local variable 'servers_and_methods' referenced before assignment
Traceback (most recent call last):
  File "attackerScript.py", line 732, in get_data
    data=attacker()
  File "/home/alex/Documents/GitRepo/IR/DataAccess.py", line 129, in __init__
    self.servers_and_methods=self.get_action()
  File "/home/alex/Documents/GitRepo/IR/DataAccess.py", line 207, in get_action
    self.servers_and_methods=servers_and_methods
UnboundLocalError: local variable 'servers_and_methods' referenced before assignment
ERROR:root:'DataAccess' object has no attribute 'service_count'
Traceback (most recent call last):
  File "DataAccess.py", line 140, in get_service
    service_count=self.data.service_count
AttributeError: 'DataAccess' object has no attribute 'service_count'
ERROR:root:'NoneType' object is not subscriptable
Traceback (most recent call last):
  File "DataAccess.py", line 184, in get_action
    service_id=self.service['service_id']
TypeError: 'NoneType' object is not subscriptable
ERROR:root:(2003, "Can't connect to MySQL server on '10.0.5.30' (timed out)")
Traceback (most recent call last):
  File "/home/alex/.local/lib/python3.5/site-packages/pymysql/connections.py", line 920, in connect
    **kwargs)
  File "/usr/lib/python3.5/socket.py", line 711, in create_connection
    raise err
  File "/usr/lib/python3.5/socket.py", line 702, in create_connection
    sock.connect(sa)
socket.timeout: timed out

During handling of the above exception, another exception occurred:

Traceback (most recent call last):
  File "DataAccess.py", line 41, in get_mysql_connection
    connection = pymysql.connect(host='10.0.5.30', user='myuser', password='1234', database='ir_db',cursorclass=pymysql.cursors.DictCursor)
  File "/home/alex/.local/lib/python3.5/site-packages/pymysql/__init__.py", line 90, in Connect
    return Connection(*args, **kwargs)
  File "/home/alex/.local/lib/python3.5/site-packages/pymysql/connections.py", line 699, in __init__
    self.connect()
  File "/home/alex/.local/lib/python3.5/site-packages/pymysql/connections.py", line 967, in connect
    raise exc
pymysql.err.OperationalError: (2003, "Can't connect to MySQL server on '10.0.5.30' (timed out)")
ERROR:root:(2003, "Can't connect to MySQL server on '10.0.5.30' ([Errno 113] No route to host)")
Traceback (most recent call last):
  File "/home/alex/.local/lib/python3.5/site-packages/pymysql/connections.py", line 920, in connect
    **kwargs)
  File "/usr/lib/python3.5/socket.py", line 711, in create_connection
    raise err
  File "/usr/lib/python3.5/socket.py", line 702, in create_connection
    sock.connect(sa)
OSError: [Errno 113] No route to host

During handling of the above exception, another exception occurred:

Traceback (most recent call last):
  File "DataAccess.py", line 41, in get_mysql_connection
    connection = pymysql.connect(host='10.0.5.30', user='myuser', password='1234', database='ir_db',cursorclass=pymysql.cursors.DictCursor)
  File "/home/alex/.local/lib/python3.5/site-packages/pymysql/__init__.py", line 90, in Connect
    return Connection(*args, **kwargs)
  File "/home/alex/.local/lib/python3.5/site-packages/pymysql/connections.py", line 699, in __init__
    self.connect()
  File "/home/alex/.local/lib/python3.5/site-packages/pymysql/connections.py", line 967, in connect
    raise exc
pymysql.err.OperationalError: (2003, "Can't connect to MySQL server on '10.0.5.30' ([Errno 113] No route to host)")
ERROR:root:The command was not found or was not executable: hydra.
Traceback (most recent call last):
  File "attackerScript.py", line 104, in hydra_spawn
    child = pexpect.spawn(command)
  File "/usr/lib/python3/dist-packages/pexpect/pty_spawn.py", line 194, in __init__
    self._spawn(command, args, preexec_fn, dimensions)
  File "/usr/lib/python3/dist-packages/pexpect/pty_spawn.py", line 267, in _spawn
    'executable: %s.' % self.command)
pexpect.exceptions.ExceptionPexpect: The command was not found or was not executable: hydra.
ERROR:root:The command was not found or was not executable: hydra.
Traceback (most recent call last):
  File "attackerScript.py", line 104, in hydra_spawn
    child = pexpect.spawn(command)
  File "/usr/lib/python3/dist-packages/pexpect/pty_spawn.py", line 194, in __init__
    self._spawn(command, args, preexec_fn, dimensions)
  File "/usr/lib/python3/dist-packages/pexpect/pty_spawn.py", line 267, in _spawn
    'executable: %s.' % self.command)
pexpect.exceptions.ExceptionPexpect: The command was not found or was not executable: hydra.
ERROR:root:list assignment index out of range
Traceback (most recent call last):
  File "attackerScript.py", line 745, in get_data
    my_dic[i]=items
IndexError: list assignment index out of range
ERROR:root:'list' object has no attribute 'items'
Traceback (most recent call last):
  File "attackerScript.py", line 47, in generate_random_request
    for key, val in service_array.items():
AttributeError: 'list' object has no attribute 'items'
ERROR:root:4
Traceback (most recent call last):
  File "attackerScript.py", line 56, in generate_random_request
    next_ip = service_array[nextElement][0]["IP"]
KeyError: 4
ERROR:root:3
Traceback (most recent call last):
  File "attackerScript.py", line 56, in generate_random_request
    next_ip = service_array[nextElement+1][0]["IP"]
KeyError: 3
ERROR:root:4
Traceback (most recent call last):
  File "attackerScript.py", line 56, in generate_random_request
    next_ip = service_array[nextElement+1][0]["IP"]
KeyError: 4
ERROR:root:4
Traceback (most recent call last):
  File "attackerScript.py", line 56, in generate_random_request
    next_ip = service_array[nextElement+1][0]["IP"]
KeyError: 4
ERROR:root:3
Traceback (most recent call last):
  File "attackerScript.py", line 56, in generate_random_request
    next_ip = service_array[nextElement+1][0]["IP"]
KeyError: 3
ERROR:root:-1
Traceback (most recent call last):
  File "attackerScript.py", line 56, in generate_random_request
    next_ip = service_array[nextElement][0]["IP"]
KeyError: -1
ERROR:root:End Of File (EOF). Exception style platform.
<pexpect.pxssh.pxssh object at 0x7f6c99caf400>
command: /usr/bin/ssh
args: ['/usr/bin/ssh', '-o', 'UserKnownHostsFile=/dev/null', '-o', 'StrictHostKeyChecking=no', '-q', '-l', 'ubuntu', '10.0.5.37']
searcher: None
buffer (last 100 chars): b''
before (last 100 chars): b"unset PROMPT_COMMAND\r\nPS1='[PEXPECT]\\$ '\r\n"
after: <class 'pexpect.exceptions.EOF'>
match: None
match_index: None
exitstatus: None
flag_eof: True
pid: 7646
child_fd: 6
closed: False
timeout: 30
delimiter: <class 'pexpect.exceptions.EOF'>
logfile: None
logfile_read: None
logfile_send: None
maxread: 2000
ignorecase: False
searchwindowsize: None
delaybeforesend: 0.05
delayafterclose: 0.1
delayafterterminate: 0.1
Traceback (most recent call last):
  File "/usr/lib/python3/dist-packages/pexpect/spawnbase.py", line 144, in read_nonblocking
    s = os.read(self.child_fd, size)
OSError: [Errno 5] Input/output error

During handling of the above exception, another exception occurred:

Traceback (most recent call last):
  File "/usr/lib/python3/dist-packages/pexpect/expect.py", line 97, in expect_loop
    incoming = spawn.read_nonblocking(spawn.maxread, timeout)
  File "/usr/lib/python3/dist-packages/pexpect/pty_spawn.py", line 455, in read_nonblocking
    return super(spawn, self).read_nonblocking(size)
  File "/usr/lib/python3/dist-packages/pexpect/spawnbase.py", line 149, in read_nonblocking
    raise EOF('End Of File (EOF). Exception style platform.')
pexpect.exceptions.EOF: End Of File (EOF). Exception style platform.

During handling of the above exception, another exception occurred:

Traceback (most recent call last):
  File "attackerScript.py", line 388, in execute_ssh_sudo
    ssh_handle.login(ip, user, password)
  File "/usr/lib/python3/dist-packages/pexpect/pxssh.py", line 337, in login
    if not self.set_unique_prompt():
  File "/usr/lib/python3/dist-packages/pexpect/pxssh.py", line 398, in set_unique_prompt
    i = self.expect ([TIMEOUT, self.PROMPT], timeout=10)
  File "/usr/lib/python3/dist-packages/pexpect/spawnbase.py", line 315, in expect
    timeout, searchwindowsize, async)
  File "/usr/lib/python3/dist-packages/pexpect/spawnbase.py", line 339, in expect_list
    return exp.expect_loop(timeout)
  File "/usr/lib/python3/dist-packages/pexpect/expect.py", line 102, in expect_loop
    return self.eof(e)
  File "/usr/lib/python3/dist-packages/pexpect/expect.py", line 49, in eof
    raise EOF(msg)
pexpect.exceptions.EOF: End Of File (EOF). Exception style platform.
<pexpect.pxssh.pxssh object at 0x7f6c99caf400>
command: /usr/bin/ssh
args: ['/usr/bin/ssh', '-o', 'UserKnownHostsFile=/dev/null', '-o', 'StrictHostKeyChecking=no', '-q', '-l', 'ubuntu', '10.0.5.37']
searcher: None
buffer (last 100 chars): b''
before (last 100 chars): b"unset PROMPT_COMMAND\r\nPS1='[PEXPECT]\\$ '\r\n"
after: <class 'pexpect.exceptions.EOF'>
match: None
match_index: None
exitstatus: None
flag_eof: True
pid: 7646
child_fd: 6
closed: False
timeout: 30
delimiter: <class 'pexpect.exceptions.EOF'>
logfile: None
logfile_read: None
logfile_send: None
maxread: 2000
ignorecase: False
searchwindowsize: None
delaybeforesend: 0.05
delayafterclose: 0.1
delayafterterminate: 0.1
ERROR:root:End Of File (EOF). Exception style platform.
<pexpect.pxssh.pxssh object at 0x7f870eb2f400>
command: /usr/bin/ssh
args: ['/usr/bin/ssh', '-o', 'StrictHostKeyChecking=no', '-o', 'UserKnownHostsFile=/dev/null', '-q', '-l', 'ubuntu', '10.0.5.37']
searcher: None
buffer (last 100 chars): b''
before (last 100 chars): b''
after: <class 'pexpect.exceptions.EOF'>
match: None
match_index: None
exitstatus: None
flag_eof: True
pid: 7777
child_fd: 6
closed: False
timeout: 30
delimiter: <class 'pexpect.exceptions.EOF'>
logfile: None
logfile_read: None
logfile_send: None
maxread: 2000
ignorecase: False
searchwindowsize: None
delaybeforesend: 0.05
delayafterclose: 0.1
delayafterterminate: 0.1
Traceback (most recent call last):
  File "/usr/lib/python3/dist-packages/pexpect/spawnbase.py", line 144, in read_nonblocking
    s = os.read(self.child_fd, size)
OSError: [Errno 5] Input/output error

During handling of the above exception, another exception occurred:

Traceback (most recent call last):
  File "/usr/lib/python3/dist-packages/pexpect/expect.py", line 97, in expect_loop
    incoming = spawn.read_nonblocking(spawn.maxread, timeout)
  File "/usr/lib/python3/dist-packages/pexpect/pty_spawn.py", line 455, in read_nonblocking
    return super(spawn, self).read_nonblocking(size)
  File "/usr/lib/python3/dist-packages/pexpect/spawnbase.py", line 149, in read_nonblocking
    raise EOF('End Of File (EOF). Exception style platform.')
pexpect.exceptions.EOF: End Of File (EOF). Exception style platform.

During handling of the above exception, another exception occurred:

Traceback (most recent call last):
  File "attackerScript.py", line 486, in execute_ssh_execute_file
    ssh_handle.login(ip, user, password)
  File "/usr/lib/python3/dist-packages/pexpect/pxssh.py", line 280, in login
    i = self.expect(["(?i)are you sure you want to continue connecting", original_prompt, "(?i)(?:password)|(?:passphrase for key)", "(?i)permission denied", "(?i)terminal type", TIMEOUT, "(?i)connection closed by remote host"], timeout=login_timeout)
  File "/usr/lib/python3/dist-packages/pexpect/spawnbase.py", line 315, in expect
    timeout, searchwindowsize, async)
  File "/usr/lib/python3/dist-packages/pexpect/spawnbase.py", line 339, in expect_list
    return exp.expect_loop(timeout)
  File "/usr/lib/python3/dist-packages/pexpect/expect.py", line 102, in expect_loop
    return self.eof(e)
  File "/usr/lib/python3/dist-packages/pexpect/expect.py", line 49, in eof
    raise EOF(msg)
pexpect.exceptions.EOF: End Of File (EOF). Exception style platform.
<pexpect.pxssh.pxssh object at 0x7f870eb2f400>
command: /usr/bin/ssh
args: ['/usr/bin/ssh', '-o', 'StrictHostKeyChecking=no', '-o', 'UserKnownHostsFile=/dev/null', '-q', '-l', 'ubuntu', '10.0.5.37']
searcher: None
buffer (last 100 chars): b''
before (last 100 chars): b''
after: <class 'pexpect.exceptions.EOF'>
match: None
match_index: None
exitstatus: None
flag_eof: True
pid: 7777
child_fd: 6
closed: False
timeout: 30
delimiter: <class 'pexpect.exceptions.EOF'>
logfile: None
logfile_read: None
logfile_send: None
maxread: 2000
ignorecase: False
searchwindowsize: None
delaybeforesend: 0.05
delayafterclose: 0.1
delayafterterminate: 0.1
ERROR:root:End Of File (EOF). Exception style platform.
<pexpect.pxssh.pxssh object at 0x7fccf4836470>
command: /usr/bin/ssh
args: ['/usr/bin/ssh', '-o', 'UserKnownHostsFile=/dev/null', '-o', 'StrictHostKeyChecking=no', '-q', '-l', 'alex', '146.64.182.181']
searcher: None
buffer (last 100 chars): b''
before (last 100 chars): b"unset PROMPT_COMMAND\r\nPS1='[PEXPECT]\\$ '\r\nset prompt='[PEXPECT]\\$ '\r\n"
after: <class 'pexpect.exceptions.EOF'>
match: None
match_index: None
exitstatus: None
flag_eof: True
pid: 7843
child_fd: 6
closed: False
timeout: 30
delimiter: <class 'pexpect.exceptions.EOF'>
logfile: None
logfile_read: None
logfile_send: None
maxread: 2000
ignorecase: False
searchwindowsize: None
delaybeforesend: 0.05
delayafterclose: 0.1
delayafterterminate: 0.1
Traceback (most recent call last):
  File "/usr/lib/python3/dist-packages/pexpect/spawnbase.py", line 144, in read_nonblocking
    s = os.read(self.child_fd, size)
OSError: [Errno 5] Input/output error

During handling of the above exception, another exception occurred:

Traceback (most recent call last):
  File "/usr/lib/python3/dist-packages/pexpect/expect.py", line 97, in expect_loop
    incoming = spawn.read_nonblocking(spawn.maxread, timeout)
  File "/usr/lib/python3/dist-packages/pexpect/pty_spawn.py", line 455, in read_nonblocking
    return super(spawn, self).read_nonblocking(size)
  File "/usr/lib/python3/dist-packages/pexpect/spawnbase.py", line 149, in read_nonblocking
    raise EOF('End Of File (EOF). Exception style platform.')
pexpect.exceptions.EOF: End Of File (EOF). Exception style platform.

During handling of the above exception, another exception occurred:

Traceback (most recent call last):
  File "attackerScript.py", line 388, in execute_ssh_sudo
    ssh_handle.login(ip, user, password)
  File "/usr/lib/python3/dist-packages/pexpect/pxssh.py", line 337, in login
    if not self.set_unique_prompt():
  File "/usr/lib/python3/dist-packages/pexpect/pxssh.py", line 401, in set_unique_prompt
    i = self.expect([TIMEOUT, self.PROMPT], timeout=10)
  File "/usr/lib/python3/dist-packages/pexpect/spawnbase.py", line 315, in expect
    timeout, searchwindowsize, async)
  File "/usr/lib/python3/dist-packages/pexpect/spawnbase.py", line 339, in expect_list
    return exp.expect_loop(timeout)
  File "/usr/lib/python3/dist-packages/pexpect/expect.py", line 102, in expect_loop
    return self.eof(e)
  File "/usr/lib/python3/dist-packages/pexpect/expect.py", line 49, in eof
    raise EOF(msg)
pexpect.exceptions.EOF: End Of File (EOF). Exception style platform.
<pexpect.pxssh.pxssh object at 0x7fccf4836470>
command: /usr/bin/ssh
args: ['/usr/bin/ssh', '-o', 'UserKnownHostsFile=/dev/null', '-o', 'StrictHostKeyChecking=no', '-q', '-l', 'alex', '146.64.182.181']
searcher: None
buffer (last 100 chars): b''
before (last 100 chars): b"unset PROMPT_COMMAND\r\nPS1='[PEXPECT]\\$ '\r\nset prompt='[PEXPECT]\\$ '\r\n"
after: <class 'pexpect.exceptions.EOF'>
match: None
match_index: None
exitstatus: None
flag_eof: True
pid: 7843
child_fd: 6
closed: False
timeout: 30
delimiter: <class 'pexpect.exceptions.EOF'>
logfile: None
logfile_read: None
logfile_send: None
maxread: 2000
ignorecase: False
searchwindowsize: None
delaybeforesend: 0.05
delayafterclose: 0.1
delayafterterminate: 0.1
ERROR:root:The command was not found or was not executable: hydra.
Traceback (most recent call last):
  File "attackerScript.py", line 114, in hydra_spawn
    child = pexpect.spawn(command)
  File "/usr/lib/python3/dist-packages/pexpect/pty_spawn.py", line 194, in __init__
    self._spawn(command, args, preexec_fn, dimensions)
  File "/usr/lib/python3/dist-packages/pexpect/pty_spawn.py", line 267, in _spawn
    'executable: %s.' % self.command)
pexpect.exceptions.ExceptionPexpect: The command was not found or was not executable: hydra.
ERROR:root:'NoneType' object is not subscriptable
Traceback (most recent call last):
  File "/home/alex/Documents/GitRepo/IR/DataAccess.py", line 164, in get_service
    checker=rep.check(service_id['service_id'])
TypeError: 'NoneType' object is not subscriptable
ERROR:root:'NoneType' object is not subscriptable
Traceback (most recent call last):
  File "/home/alex/Documents/GitRepo/IR/DataAccess.py", line 193, in get_action
    service_id=self.service['service_id']
TypeError: 'NoneType' object is not subscriptable
ERROR:root:local variable 'servers_and_methods' referenced before assignment
Traceback (most recent call last):
  File "attackerScript.py", line 742, in get_data
    data=attacker()
  File "/home/alex/Documents/GitRepo/IR/DataAccess.py", line 139, in __init__
    self.servers_and_methods=self.get_action()
  File "/home/alex/Documents/GitRepo/IR/DataAccess.py", line 216, in get_action
    self.servers_and_methods=servers_and_methods
UnboundLocalError: local variable 'servers_and_methods' referenced before assignment
ERROR:root:'NoneType' object is not subscriptable
Traceback (most recent call last):
  File "/home/alex/Documents/GitRepo/IR/DataAccess.py", line 164, in get_service
    checker=rep.check(service_id['service_id'])
TypeError: 'NoneType' object is not subscriptable
ERROR:root:'NoneType' object is not subscriptable
Traceback (most recent call last):
  File "/home/alex/Documents/GitRepo/IR/DataAccess.py", line 193, in get_action
    service_id=self.service['service_id']
TypeError: 'NoneType' object is not subscriptable
ERROR:root:local variable 'servers_and_methods' referenced before assignment
Traceback (most recent call last):
  File "attackerScript.py", line 742, in get_data
    data=attacker()
  File "/home/alex/Documents/GitRepo/IR/DataAccess.py", line 139, in __init__
    self.servers_and_methods=self.get_action()
  File "/home/alex/Documents/GitRepo/IR/DataAccess.py", line 216, in get_action
    self.servers_and_methods=servers_and_methods
UnboundLocalError: local variable 'servers_and_methods' referenced before assignment
ERROR:root:'NoneType' object is not subscriptable
Traceback (most recent call last):
  File "/home/alex/Documents/GitRepo/IR/DataAccess.py", line 164, in get_service
    checker=rep.check(service_id['service_id'])
TypeError: 'NoneType' object is not subscriptable
ERROR:root:'NoneType' object is not subscriptable
Traceback (most recent call last):
  File "/home/alex/Documents/GitRepo/IR/DataAccess.py", line 193, in get_action
    service_id=self.service['service_id']
TypeError: 'NoneType' object is not subscriptable
ERROR:root:local variable 'servers_and_methods' referenced before assignment
Traceback (most recent call last):
  File "attackerScript.py", line 742, in get_data
    data=attacker()
  File "/home/alex/Documents/GitRepo/IR/DataAccess.py", line 139, in __init__
    self.servers_and_methods=self.get_action()
  File "/home/alex/Documents/GitRepo/IR/DataAccess.py", line 216, in get_action
    self.servers_and_methods=servers_and_methods
UnboundLocalError: local variable 'servers_and_methods' referenced before assignment
ERROR:root:'NoneType' object is not subscriptable
Traceback (most recent call last):
  File "DataAccess.py", line 164, in get_service
    checker=rep.check(service_id['service_id'])
TypeError: 'NoneType' object is not subscriptable
ERROR:root:'NoneType' object is not subscriptable
Traceback (most recent call last):
  File "DataAccess.py", line 193, in get_action
    service_id=self.service['service_id']
TypeError: 'NoneType' object is not subscriptable
ERROR:root:Packet sequence number wrong - got 3 expected 1
Traceback (most recent call last):
  File "DataAccess.py", line 61, in get_service
    cursor.execute(sql)
  File "/home/alex/.local/lib/python3.5/site-packages/pymysql/cursors.py", line 165, in execute
    result = self._query(query)
  File "/home/alex/.local/lib/python3.5/site-packages/pymysql/cursors.py", line 321, in _query
    conn.query(q)
  File "/home/alex/.local/lib/python3.5/site-packages/pymysql/connections.py", line 860, in query
    self._affected_rows = self._read_query_result(unbuffered=unbuffered)
  File "/home/alex/.local/lib/python3.5/site-packages/pymysql/connections.py", line 1061, in _read_query_result
    result.read()
  File "/home/alex/.local/lib/python3.5/site-packages/pymysql/connections.py", line 1356, in read
    self._read_result_packet(first_packet)
  File "/home/alex/.local/lib/python3.5/site-packages/pymysql/connections.py", line 1421, in _read_result_packet
    self._get_descriptions()
  File "/home/alex/.local/lib/python3.5/site-packages/pymysql/connections.py", line 1492, in _get_descriptions
    field = self.connection._read_packet(FieldDescriptorPacket)
  File "/home/alex/.local/lib/python3.5/site-packages/pymysql/connections.py", line 1017, in _read_packet
    packet = packet_type(buff, self.encoding)
  File "/home/alex/.local/lib/python3.5/site-packages/pymysql/connections.py", line 399, in __init__
    self._parse_field_descriptor(encoding)
  File "/home/alex/.local/lib/python3.5/site-packages/pymysql/connections.py", line 406, in _parse_field_descriptor
    self.catalog = self.read_length_coded_string()
  File "/home/alex/.local/lib/python3.5/site-packages/pymysql/connections.py", line 343, in read_length_coded_string
    length = self.read_length_encoded_integer()
  File "/home/alex/.local/lib/python3.5/site-packages/pymysql/connections.py", line 324, in read_length_encoded_integer
    c = self.read_uint8()
RecursionError: maximum recursion depth exceeded

During handling of the above exception, another exception occurred:

Traceback (most recent call last):
  File "DataAccess.py", line 62, in get_service
    result = cursor.fetchone()
  File "/home/alex/.local/lib/python3.5/site-packages/pymysql/connections.py", line 846, in __exit__
    self.rollback()
  File "/home/alex/.local/lib/python3.5/site-packages/pymysql/connections.py", line 786, in rollback
    self._read_ok_packet()
  File "/home/alex/.local/lib/python3.5/site-packages/pymysql/connections.py", line 760, in _read_ok_packet
    pkt = self._read_packet()
  File "/home/alex/.local/lib/python3.5/site-packages/pymysql/connections.py", line 1005, in _read_packet
    % (packet_number, self._next_seq_id))
pymysql.err.InternalError: Packet sequence number wrong - got 3 expected 1
ERROR:root:local variable 'result' referenced before assignment
Traceback (most recent call last):
  File "DataAccess.py", line 158, in get_service
    service_id= self.data.get_service(1)
  File "DataAccess.py", line 68, in get_service
    return result
UnboundLocalError: local variable 'result' referenced before assignment
ERROR:root:(0, '')
Traceback (most recent call last):
  File "DataAccess.py", line 105, in get_action
    cursor.execute(sql)
  File "/home/alex/.local/lib/python3.5/site-packages/pymysql/cursors.py", line 165, in execute
    result = self._query(query)
  File "/home/alex/.local/lib/python3.5/site-packages/pymysql/cursors.py", line 321, in _query
    conn.query(q)
  File "/home/alex/.local/lib/python3.5/site-packages/pymysql/connections.py", line 859, in query
    self._execute_command(COMMAND.COM_QUERY, sql)
  File "/home/alex/.local/lib/python3.5/site-packages/pymysql/connections.py", line 1075, in _execute_command
    raise err.InterfaceError("(0, '')")
pymysql.err.InterfaceError: (0, '')

During handling of the above exception, another exception occurred:

Traceback (most recent call last):
  File "DataAccess.py", line 106, in get_action
    result = cursor.fetchall()
  File "/home/alex/.local/lib/python3.5/site-packages/pymysql/connections.py", line 846, in __exit__
    self.rollback()
  File "/home/alex/.local/lib/python3.5/site-packages/pymysql/connections.py", line 785, in rollback
    self._execute_command(COMMAND.COM_QUERY, "ROLLBACK")
  File "/home/alex/.local/lib/python3.5/site-packages/pymysql/connections.py", line 1075, in _execute_command
    raise err.InterfaceError("(0, '')")
pymysql.err.InterfaceError: (0, '')
ERROR:root:local variable 'result' referenced before assignment
Traceback (most recent call last):
  File "DataAccess.py", line 195, in get_action
    action_list=self.data.get_action(service_id)
  File "DataAccess.py", line 112, in get_action
    return result
UnboundLocalError: local variable 'result' referenced before assignment
ERROR:root:'NoneType' object is not subscriptable
Traceback (most recent call last):
  File "DataAccess.py", line 164, in get_service
    checker=rep.check(service_id['service_id'])
TypeError: 'NoneType' object is not subscriptable
ERROR:root:'NoneType' object is not subscriptable
Traceback (most recent call last):
  File "DataAccess.py", line 193, in get_action
    service_id=self.service['service_id']
TypeError: 'NoneType' object is not subscriptable
ERROR:root:'NoneType' object is not subscriptable
Traceback (most recent call last):
  File "DataAccess.py", line 164, in get_service
    checker=rep.check(service_id['service_id'])
TypeError: 'NoneType' object is not subscriptable
ERROR:root:'NoneType' object is not subscriptable
Traceback (most recent call last):
  File "DataAccess.py", line 194, in get_action
    service_id=self.service['service_id']
TypeError: 'NoneType' object is not subscriptable
ERROR:root:'NoneType' object is not subscriptable
Traceback (most recent call last):
  File "DataAccess.py", line 164, in get_service
    checker=rep.check(service_id['service_id'])
TypeError: 'NoneType' object is not subscriptable
ERROR:root:'NoneType' object is not subscriptable
Traceback (most recent call last):
  File "DataAccess.py", line 194, in get_action
    service_id=self.service['service_id']
TypeError: 'NoneType' object is not subscriptable
ERROR:root:'NoneType' object is not subscriptable
Traceback (most recent call last):
  File "DataAccess.py", line 164, in get_service
    checker=rep.check(service_id['service_id'])
TypeError: 'NoneType' object is not subscriptable
ERROR:root:'NoneType' object is not subscriptable
Traceback (most recent call last):
  File "DataAccess.py", line 196, in get_action
    service_id=self.service['service_id']
TypeError: 'NoneType' object is not subscriptable
ERROR:root:'NoneType' object is not subscriptable
Traceback (most recent call last):
  File "DataAccess.py", line 164, in get_service
    checker=rep.check(service_id['service_id'])
TypeError: 'NoneType' object is not subscriptable
ERROR:root:'NoneType' object is not subscriptable
Traceback (most recent call last):
  File "DataAccess.py", line 196, in get_action
    service_id=self.service['service_id']
TypeError: 'NoneType' object is not subscriptable
ERROR:root:'NoneType' object is not subscriptable
Traceback (most recent call last):
  File "DataAccess.py", line 164, in get_service
    checker=rep.check(service_id['service_id'])
TypeError: 'NoneType' object is not subscriptable
ERROR:root:execute_web_create_file() takes 0 positional arguments but 1 was given
Traceback (most recent call last):
  File "attackerScript.py", line 92, in call_class_method
    the_method = getattr(attackerClass,method)(values)
TypeError: execute_web_create_file() takes 0 positional arguments but 1 was given
